Workbook

Sheet empty sheet
I1: DATE | J1: 46113
E3: RemiseBancaire(SAP) | I3: EXCEL
E4: Espèces | I4: ESPECES | K4: =E80+C14 -> 0
E5: Chèques | I5: CHEQUES | K5: =E15+E81 -> 0
E6: Monnaienondéposée | I6: CARTECREDIT | K6: =G15+E82 -> 0
I7: VIREMENT | K7: =SUM(E59:E64) -> 0
B8: CaisseEspèces | D8: Caissechèques | F8: CaisseCB
B9: Billetsde50 | D9: Client | E9: Montant | F9: Client | G9: Montant | I9: Dépenses:Essence,Divers | L9: Montant
B10: Billetsde20 | F10: Till
B11: Billetsde10 | F11: sancont
B12: Billetsde5
B13: Monnaie
B14: Total | C14: =SUM(C9:C13) -> 0
B15: Fonddecaisse | C15: 461 | D15: Total | E15: =SUM(E10:E14) -> 0 | F15: Total | G15: =SUM(G10:G14) -> 0 | I15: DifférenceFondCaisse
K16: Total | L16: =(SUM(L10:L15))*1 -> 0
A18: LIVRAISONS
A19: CODECLIENT | B19: PaiementsChèques | E19: Montant | F19: Banque | G19: Numero | H19: Remarques | L19: SAP
A38: CODECLIENT | B38: PaiementsEspèces | E38: Montant | F38: Remarques | L38: SAP
A48: CODECLIENT | B48: PaiementsCBSite | E48: Montant | F48: Remarques | L48: SAP
A53: CODECLIENT | B53: PaiementsCBTéléphone | E53: Montant | F53: Remarques | L53: SAP
C54: 802.36 | D54: cari versailles
C55: 675.28 | D55: cqfd
C56: 689.72 | D56: cqfd
C57: 340.26 | D57: new
A58: CODECLIENT | B58: Virements | E58: Montant | F58: Remarques | L58: SAP
A65: CODECLIENT | B65: Livraisonsnonpayées | E65: Montant | F65: Remarques | L65: SAP
B80: TOTALESPECES | E80: =SUM(E39:E47) -> 0
B81: TOTALCHEQUES | E81: =SUM(E20:E37) -> 0
B82: TOTALCBInternet&Phone | E82: =SUM(E49:E57) -> 0

Sheet 1
I1: DATE | J1: 46113
G2: no002804193330
E3: RemiseBancaire(SAP) | G3: no002804393210 | I3: EXCEL
E4: Espèces | F4: 9640 | G4: no002804243100 | I4: ESPECES | K4: =E82+C14 -> 9653.02
E5: Chèques | F5: 4711.78 | G5: no104711,78 | I5: CHEQUES | K5: =E15+E83 -> 4711.78
E6: Monnaienondéposée | F6: 13.02 | I6: CARTECREDIT | K6: =G15+E84 -> 16314.77
I7: VIREMENT | K7: =SUM(E58:E63) -> 0
B8: CaisseEspèces | D8: Caissechèques | F8: CaisseCB
B9: Billetsde50 | C9: 2300 | D9: Client | E9: Montant | F9: Client | G9: Montant | I9: Dépenses:Essence,Divers | L9: Montant
B10: Billetsde20 | C10: 3100 | D10: alishanrest | E10: 530.06 | F10: Till | G10: 16314.77 | I10: ahmedgasoil | L10: 80
B11: Billetsde10 | C11: 2300 | F11: sancont | I11: abubakaradvancemars2026 | L11: 600
B12: Billetsde5 | C12: 120
B13: Monnaie
B14: Total | C14: =SUM(C9:C13) -> 7820
B15: Fonddecaisse | C15: 713 | D15: Total | E15: =SUM(E10:E14) -> 530.06 | F15: Total | G15: =SUM(G10:G14) -> 16314.77 | I15: DifférenceFondCaisse | L15: =C15+[1]emptysheet!C15 -> #REF!
K16: Total | L16: =(SUM(L10:L15))*-1 -> #REF!
A18: LIVRAISONS
A19: CODECLIENT | B19: PaiementsChèques | E19: Montant | F19: Banque | G19: Numero | H19: Remarques | L19: SAP
A20: c4494 | B20: MCVDaumesnil | E20: 284.64 | F20: bred | G20: 8622364 | L20: ok
A21: c5362 | B21: ChezSUZETTE | E21: 300.51 | F21: lcl | G21: 2719859 | L21: ok
A22: c6616 | B22: SIRIUS | E22: 569.09 | F22: cic | G22: 4163035 | L22: ok
A23: c1756 | B23: davodistribution | E23: 918.2 | F23: lcl | G23: 4947306 | L23: ok
A24: c4168 | B24: restaurantk-chimaek | E24: 214.57 | F24: bnp | G24: 214.57 | L24: ok
A25: c5205 | B25: restaurantyoshiworld | E25: 278.15 | F25: ce | G25: 705 | L25: ok
A26: c4903 | B26: ROOSTERGRILLlam | E26: 311.96 | F26: ca | G26: 2265447 | L26: ok
A27: c4650 | B27: BREADSHOP | E27: 815.99 | F27: bp | G27: 2362 | L27: ok
A28: c7664 | B28: RestaurantCheezy | E28: 488.61 | F28: bnp | G28: 2693023 | L28: ok
A37: CODECLIENT | B37: PaiementsEspèces | E37: Montant | F37: Remarques | L37: SAP
A38: c6054 | B38: JadwigaWala | E38: 910.68 | L38: ok
A39: c3017 | B39: PFCARDINET(MATHIEUBoulangerie) | E39: 449.98 | L39: ok
A40: c4332 | B40: YBB | E40: 394.36 | L40: ok
B41: echangemonnais | E41: 78
A47: CODECLIENT | B47: PaiementsCBSite | E47: Montant | F47: Remarques | L47: SAP
A52: CODECLIENT | B52: PaiementsCBTéléphone | E52: Montant | F52: Remarques | L52: SAP
C53: 802.36 | D53: cari versailles
C54: 675.28 | D54: cqfd
C55: 689.72 | D55: cqfd
C56: 340.26 | D56: new
A57: CODECLIENT | B57: Virements | E57: Montant | F57: Remarques | L57: SAP
A64: CODECLIENT | B64: Livraisonsnonpayées | E64: Montant | F64: Remarques | L64: SAP
...

Sheet 2
I1: DATE | J1: 46114
E3: RemiseBancaire(SAP) | G3: NO002804044130 | I3: EXCEL
E4: Espèces | F4: 7170 | G4: NO002803923040 | I4: ESPECES | K4: =E106+C14 -> 7173.88
E5: Chèques | F5: 9424.09 | G5: NO159424,09 | I5: CHEQUES | K5: =E15+E107 -> 9424.09
E6: Monnaienondéposée | F6: 3.88 | I6: CARTECREDIT | K6: =G15+E108 -> 41292.76
I7: VIREMENT | K7: =SUM(E74:E79) -> 0
B8: CaisseEspèces | D8: Caissechèques | F8: CaisseCB
B9: Billetsde50 | C9: 3300 | D9: Client | E9: Montant | F9: Client | G9: Montant | I9: Dépenses:Essence,Divers | L9: Montant
B10: Billetsde20 | C10: 1500 | D10: AUSUNDINE | E10: 391.29 | F10: Till | G10: 24011.5 | I10: amar | L10: 150
B11: Billetsde10 | C11: 690 | D11: OSPERSAN | E11: 1339.14 | F11: sancont | I11: samir | L11: 80
B12: Billetsde5 | C12: 140 | D12: ALISHANREST | E12: 283.35 | I12: skander | L12: 40
B13: Monnaie | I13: HOUCINE | L13: 80
B14: Total | C14: =SUM(C9:C13) -> 5630
B15: Fonddecaisse | C15: 536 | D15: Total | E15: =SUM(E10:E14) -> 2013.78 | F15: Total | G15: =SUM(G10:G14) -> 24011.5 | I15: DifférenceFondCaisse | L15: =C15-'1'!C15 -> -177
K16: Total | L16: =(SUM(L10:L15))*-1 -> -173
A18: LIVRAISONS
A19: CODECLIENT | B19: PaiementsChèques | E19: Montant | F19: Banque | G19: Numero | H19: Remarques | L19: SAP
A20: c6684 | B20: SOCIETEJH | E20: 373.97 | F20: sg | G20: 3840 | L20: ok
A21: c5420 | B21: Davidwarmuz | E21: 1003.9 | F21: lcl | G21: 2089630 | L21: ok
A22: c3757 | B22: SASTHON | E22: 338.35 | F22: lcl | G22: 9334211 | L22: OK
A23: C6651 | B23: ParissudEntreprise | E23: 505.37 | F23: BNP | G23: 7010120 | L23: OK
A24: c3476 | B24: VICTORIA168 | E24: 612.93 | F24: sg | G24: 297 | L24: ok
A25: c5238 | B25: Royalkebab | E25: 239.25 | F25: cm | G25: 5467728 | L25: ok
A26: c6124 | B26: A,M,C, | E26: 2339.63 | F26: lcl | G26: 3193128 | L26: ok
A27: c5499 | B27: LATIFAAFIF | E27: 410.47 | F27: sg | G27: 17 | L27: ok
A28: c541 | B28: SarlCdr | E28: 365.31 | F28: bp | G28: 251 | L28: ok
A29: c5435 | B29: Massis | E29: 489.13 | F29: sg | G29: 153 | L29: ok
A30: C5776 | B30: HaochiLI | E30: 282.65 | F30: BNP | G30: 878366 | L30: OK
A31: C6508 | B31: RannouchExpress | E31: 449.35 | F31: BNP | G31: 1681098 | L31: ok
A38: CODECLIENT | B38: PaiementsEspèces | E38: Montant | F38: Remarques | L38: SAP
A39: C6054 | B39: JadwigaWala | E39: 955.13 | L39: OK
A40: c5824 | B40: OBADAALMALLOUHI | E40: 328.18 | L40: ok
A41: c7030 | B41: OPUS | E41: 260.57 | L41: ok
A48: CODECLIENT | B48: PaiementsCBSite | E48: Montant | F48: Remarques | L48: SAP
A49: C4084 | B49: SOGEMAT | E49: 4233.82 | F49: EXTRA | L49: OK
A50: C5977 | C50: brandecision | E50: 3072.96 | L50: OK
A51: C7596 | C51: DEEPKITCHEN | E51: 2865.97 | L51: OK
A52: C6886 | C52: Lafourneedines | E52: 1290.22 | L52: OK
A53: C6735 | C53: Dolcedessert | E53: 1381.31 | L53: OK
A54: C7191 | C54: O'Tacos-MCLDISTRIBUTION | E54: 540.67 | L54: OK
...

Sheet 3
I1: DATE | J1: 46115
E3: RemiseBancaire(SAP) | G3: NO002803873485 | I3: EXCEL
E4: Espèces | F4: 10145 | G4: NO002803726660 | I4: ESPECES | K4: =E97+C14 -> 10149.46
E5: Chèques | F5: 2751.14 | G5: NO62751,14 | I5: CHEQUES | K5: =E15+E98 -> 2751.14
E6: Monnaienondéposée | F6: 4.5 | I6: CARTECREDIT | K6: =G15+E99 -> 37509.36
I7: VIREMENT | K7: =SUM(E73:E78) -> 0
B8: CaisseEspèces | D8: Caissechèques | F8: CaisseCB
B9: Billetsde50 | C9: 5150 | D9: Client | E9: Montant | F9: Client | G9: Montant | I9: Dépenses:Essence,Divers | L9: Montant
B10: Billetsde20 | C10: 1880 | D10: l'emeraude | E10: 466.53 | F10: Till | G10: 10834.72 | I10: skandergasoil | L10: 80
B11: Billetsde10 | C11: 2480 | D11: alishanrest | E11: 253.53 | F11: sancont | I11: SAMIRGASOIL | L11: 150
B12: Billetsde5 | D12: maxchicken | E12: 730.5 | I12: HOCINEACOMPTE | L12: 100
B13: Monnaie
B14: Total | C14: =SUM(C9:C13) -> 9510
B15: Fonddecaisse | D15: Total | E15: =SUM(E10:E14) -> 1450.56 | F15: Total | G15: =SUM(G10:G14) -> 10834.72 | I15: DifférenceFondCaisse | L15: =C15-'2'!C15 -> -536
K16: Total | L16: =(SUM(L10:L15))*-1 -> 206
A18: LIVRAISONS
A19: CODECLIENT | B19: PaiementsChèques | E19: Montant | F19: Banque | G19: Numero | H19: Remarques | L19: SAP
A20: C3215 | B20: AZAR | E20: 704.82 | F20: BP | G20: 222 | L20: OK
A21: c1936 | B21: LEPHENIX | E21: 297.5 | F21: ca | G21: 857179 | L21: ok
A22: c6940 | B22: mcvlavillette | E22: 298.26 | F22: sg | G22: 71 | L22: OK
A38: CODECLIENT | B38: PaiementsEspèces | E38: Montant | F38: Remarques | L38: SAP
A39: c5702 | B39: fahad | E39: 325 | L39: ok
A40: c7730 | B40: marvin | E40: 314.46 | L40: ok
A48: CODECLIENT | B48: PaiementsCBSite | E48: Montant | F48: Remarques | L48: SAP
A49: C6663 | B49: M,Comptoir | E49: 2705.81 | L49: OK
A50: C5977 | C50: brandecision | E50: 7000 | L50: OK
A51: C5977 | C51: brandecision | E51: 6500 | L51: OK
A52: C7196 | C52: LIDISTRIBUTION | E52: 2006.45 | L52: OK
A53: C7451 | C53: BigBangZone | E53: 2063.55 | L53: OK
A54: C6727 | C54: SODIMACLuzzato | E54: 2270.4 | L54: OK
A55: C6108 | C55: LEROCHER | E55: 285.86 | L55: OK
A56: C7604 | C56: maximestefanos | E56: 514.87 | L56: OK
A57: C5977 | C57: BRANDECISION | E57: 967.35 | L57: OK
A58: c7505 | C58: WAJIHHAMMOUD | E58: 307.75 | L58: OK
A59: C6555 | C59: AhmedBellahcene | E59: 1292 | L59: OK
A60: C2718 | C60: LILIANE&ILIANE | E60: 365.19 | L60: OK
A61: C2718 | C61: LILIANE&ILIANE | E61: 395.41 | L61: OK
A67: CODECLIENT | B67: PaiementsCBTéléphone | E67: Montant | F67: Remarques | L67: SAP
A68: c3218 | B68: EXTRAM,N,A | C68: 802.36 | D68: cari versailles | F68: 354.91 | L68: OK
C69: 675.28 | D69: cqfd
...

Sheet 4
G1: NO002803671670 | I1: DATE | J1: 46116
G2: NO002803323120
E3: RemiseBancaire(SAP) | G3: NO002803522180 | I3: EXCEL
E4: Espèces | F4: 13470 | G4: NO002803476500 | I4: ESPECES | K4: =E80+C14 -> 13470
E5: Chèques | F5: 1608.59 | G5: NO31608,59 | I5: CHEQUES | K5: =E15+E81 -> 1608.59
E6: Monnaienondéposée | I6: CARTECREDIT | K6: =G15+E82 -> 25778.66
I7: VIREMENT | K7: =SUM(E59:E64) -> 0
B8: CaisseEspèces | D8: Caissechèques | F8: CaisseCB
B9: Billetsde50 | C9: 6500 | D9: Client | E9: Montant | F9: Client | G9: Montant | I9: Dépenses:Essence,Divers | L9: Montant
B10: Billetsde20 | C10: 4220 | D10: BUFFETGARE | E10: 549.44 | F10: Till | G10: 25778.66 | I10: AHMEDGASOIL | L10: 80
B11: Billetsde10 | C11: 2540 | D11: BESTFALAFEL | E11: 531.42 | F11: sancont | I11: SKENDARGASOIL | L11: 80
B12: Billetsde5 | C12: 210 | D12: ALISHAN | E12: 527.73 | I12: SAMIRTRANSPORTER | L12: 250
B13: Monnaie
B14: Total | C14: =SUM(C9:C13) -> 13470
B15: Fonddecaisse | C15: 596 | D15: Total | E15: =SUM(E10:E14) -> 1608.59 | F15: Total | G15: =SUM(G10:G14) -> 25778.66 | I15: DifférenceFondCaisse | L15: =C15-'3'!C15 -> 596
K16: Total | L16: =(SUM(L10:L15))*-1 -> -1006
A18: LIVRAISONS
A19: CODECLIENT | B19: PaiementsChèques | E19: Montant | F19: Banque | G19: Numero | H19: Remarques | L19: SAP
A38: CODECLIENT | B38: PaiementsEspèces | E38: Montant | F38: Remarques | L38: SAP
A48: CODECLIENT | B48: PaiementsCBSite | E48: Montant | F48: Remarques | L48: SAP
A53: CODECLIENT | B53: PaiementsCBTéléphone | E53: Montant | F53: Remarques | L53: SAP
C54: 802.36 | D54: cari versailles
C55: 675.28 | D55: cqfd
C56: 689.72 | D56: cqfd
C57: 340.26 | D57: new
A58: CODECLIENT | B58: Virements | E58: Montant | F58: Remarques | L58: SAP
A65: CODECLIENT | B65: Livraisonsnonpayées | E65: Montant | F65: Remarques | L65: SAP
B80: TOTALESPECES | E80: =SUM(E39:E47) -> 0
B81: TOTALCHEQUES | E81: =SUM(E20:E37) -> 0
B82: TOTALCBInternet&Phone | E82: =SUM(E49:E57) -> 0

Sheet 5
I1: DATE | J1: 46117
E3: RemiseBancaire(SAP) | I3: EXCEL
E4: Espèces | I4: ESPECES | K4: =E80+C14 -> 0
E5: Chèques | I5: CHEQUES | K5: =E15+E81 -> 0
E6: Monnaienondéposée | I6: CARTECREDIT | K6: =G15+E82 -> 0
I7: VIREMENT | K7: =SUM(E59:E64) -> 0
B8: CaisseEspèces | D8: Caissechèques | F8: CaisseCB
B9: Billetsde50 | D9: Client | E9: Montant | F9: Client | G9: Montant | I9: Dépenses:Essence,Divers | L9: Montant
B10: Billetsde20 | F10: Till
B11: Billetsde10 | F11: sancont
B12: Billetsde5
B13: Monnaie
B14: Total | C14: =SUM(C9:C13) -> 0
B15: Fonddecaisse | D15: Total | E15: =SUM(E10:E14) -> 0 | F15: Total | G15: =SUM(G10:G14) -> 0 | I15: DifférenceFondCaisse | L15: =C15-'4'!C15 -> -596
K16: Total | L16: =(SUM(L10:L15))*-1 -> 596
A18: LIVRAISONS
A19: CODECLIENT | B19: PaiementsChèques | E19: Montant | F19: Banque | G19: Numero | H19: Remarques | L19: SAP
A38: CODECLIENT | B38: PaiementsEspèces | E38: Montant | F38: Remarques | L38: SAP
A48: CODECLIENT | B48: PaiementsCBSite | E48: Montant | F48: Remarques | L48: SAP
A53: CODECLIENT | B53: PaiementsCBTéléphone | E53: Montant | F53: Remarques | L53: SAP
C54: 802.36 | D54: cari versailles
C55: 675.28 | D55: cqfd
C56: 689.72 | D56: cqfd
C57: 340.26 | D57: new
A58: CODECLIENT | B58: Virements | E58: Montant | F58: Remarques | L58: SAP
A65: CODECLIENT | B65: Livraisonsnonpayées | E65: Montant | F65: Remarques | L65: SAP
B80: TOTALESPECES | E80: =SUM(E39:E47) -> 0
B81: TOTALCHEQUES | E81: =SUM(E20:E37) -> 0
B82: TOTALCBInternet&Phone | E82: =SUM(E49:E57) -> 0

Sheet 6
I1: DATE | J1: 46118
G2: NO002803271610
E3: RemiseBancaire(SAP) | G3: NO002803075110 | I3: EXCEL
E4: Espèces | F4: 10440 | G4: NO002803123720 | I4: ESPECES | K4: =E80+C14 -> 10440
E5: Chèques | F5: 1400.18 | G5: NO21400,18 | I5: CHEQUES | K5: =E15+E81 -> 1400.18
E6: Monnaienondéposée | I6: CARTECREDIT | K6: =G15+E82 -> 22371.77
I7: VIREMENT | K7: =SUM(E59:E64) -> 0
B8: CaisseEspèces | D8: Caissechèques | F8: CaisseCB
B9: Billetsde50 | C9: 3800 | D9: Client | E9: Montant | F9: Client | G9: Montant | I9: Dépenses:Essence,Divers | L9: Montant
B10: Billetsde20 | C10: 3580 | D10: ALISHANREST | E10: 545.99 | F10: Till | G10: 22371.77 | I10: HOCINEADBLU | L10: 32.5
B11: Billetsde10 | C11: 2920 | D11: AUSUNDINE | E11: 854.19 | F11: sancont | I11: AHMEDGASOIL | L11: 80
B12: Billetsde5 | C12: 140
B13: Monnaie
B14: Total | C14: =SUM(C9:C13) -> 10440
B15: Fonddecaisse | C15: 544 | D15: Total | E15: =SUM(E10:E14) -> 1400.18 | F15: Total | G15: =SUM(G10:G14) -> 22371.77 | I15: DifférenceFondCaisse | L15: =C15-'5'!C15 -> 544
K16: Total | L16: =(SUM(L10:L15))*-1 -> -656.5
A18: LIVRAISONS
A19: CODECLIENT | B19: PaiementsChèques | E19: Montant | F19: Banque | G19: Numero | H19: Remarques | L19: SAP
A38: CODECLIENT | B38: PaiementsEspèces | E38: Montant | F38: Remarques | L38: SAP
A48: CODECLIENT | B48: PaiementsCBSite | E48: Montant | F48: Remarques | L48: SAP
A53: CODECLIENT | B53: PaiementsCBTéléphone | E53: Montant | F53: Remarques | L53: SAP
C54: 802.36 | D54: cari versailles
C55: 675.28 | D55: cqfd
C56: 689.72 | D56: cqfd
C57: 340.26 | D57: new
A58: CODECLIENT | B58: Virements | E58: Montant | F58: Remarques | L58: SAP
A65: CODECLIENT | B65: Livraisonsnonpayées | E65: Montant | F65: Remarques | L65: SAP
B80: TOTALESPECES | E80: =SUM(E39:E47) -> 0
B81: TOTALCHEQUES | E81: =SUM(E20:E37) -> 0
B82: TOTALCBInternet&Phone | E82: =SUM(E49:E57) -> 0

Sheet 7
I1: DATE | J1: 46119
E3: RemiseBancaire(SAP) | G3: no002802805115 | I3: EXCEL
E4: Espèces | F4: 7265 | G4: no002802952150 | I4: ESPECES | K4: =E120+C14 -> 7276.35
E5: Chèques | F5: 13592.29 | G5: no1913592,29 | I5: CHEQUES | K5: =E15+E121 -> 13592.29
E6: Monnaienondéposée | F6: 11.35 | I6: CARTECREDIT | K6: =G15+E122 -> 27275.98
I7: VIREMENT | K7: =SUM(E58:E73) -> 18382.79
B8: CaisseEspèces | D8: Caissechèques | F8: CaisseCB
B9: Billetsde50 | C9: 2200 | D9: Client | E9: Montant | F9: Client | G9: Montant | I9: Dépenses:Essence,Divers | L9: Montant
B10: Billetsde20 | C10: 1820 | D10: 3afood | E10: 277.37 | F10: Till | G10: 26103.54 | I10: houcine | L10: 80
B11: Billetsde10 | C11: 2150 | D11: delta | E11: 3520.07 | F11: sancont
B12: Billetsde5 | C12: 30 | I12: aboubaker | L12: 85.85
B13: Monnaie | I13: samirgasoiletadblu | L13: 230
B14: Total | C14: =SUM(C9:C13) -> 6200 | I14: plumber | L14: 600
B15: Fonddecaisse | C15: 451 | D15: Total | E15: =SUM(E10:E14) -> 3797.44 | F15: Total | G15: =SUM(G10:G14) -> 26103.54 | I15: DifférenceFondCaisse | L15: =C15-'6'!C15 -> -93
K16: Total | L16: =(SUM(L10:L15))*-1 -> -902.85
A18: LIVRAISONS
A19: CODECLIENT | B19: PaiementsChèques | E19: Montant | F19: Banque | G19: Numero | H19: Remarques | L19: SAP
A20: c3237 | B20: LEMAGHREB | E20: 685.52 | F20: lcl | G20: 6786163 | L20: ok
A21: c7637 | B21: CHIKENFRENZY | E21: 2241.89 | F21: lcl | G21: 6155355 | L21: ok
A22: c1855 | B22: FRANPRIXSAVU | E22: 346.62 | F22: lcl | G22: 4142817 | L22: ok
A23: c4548 | B23: COTEPIGALLE | E23: 299.89 | F23: bp | G23: 493 | L23: ok
A24: c1842 | B24: GUOCHENG | E24: 573.51 | F24: ca | G24: 2916564 | L24: ok
A25: c4204 | B25: Kashmirexpress | E25: 302.95 | F25: lcl | G25: 2722680 | L25: ok
A26: c5161 | B26: K-CHI | E26: 339 | F26: bnp | G26: 9427205 | L26: ok
A27: c3476 | B27: VICTORIA168 | E27: 656.13 | F27: sg | G27: 298 | L27: ok
A28: c5707 | B28: BibimElancourt | E28: 425.53 | F28: ca | G28: 473 | L28: ok
A29: c1428 | B29: NOUJOUM | E29: 246.1 | F29: ca | G29: 2032 | L29: ok
A30: c2987 | B30: boulangerielespoètes | E30: 488.65 | F30: caissedepargne | G30: 697 | L30: ok
A31: c6940 | B31: MCVLAVILLETTE | E31: 375.16 | F31: sg | G31: 72 | L31: ok
... A36: c1376 | B36: DELICEHOUSESUSHIWASABI | E36: 368.32 | F36: ce | G36: 9978481 | L36: ok
A37: CODECLIENT | B37: PaiementsEspèces | E37: Montant | F37: Remarques | L37: SAP
B38: retourhoucine | E38: 12.5 | F38: gasoil
A39: c2431 | B39: ARGENSONETSEPTARPENTS | E39: 160 | L39: ok
A40: c2414 | B40: LAROTISSERIE | E40: 393.37 | L40: ok
A41: c5276 | B41: Silan | E41: 352.26 | L41: ok
B42: CookandFood | E42: 158.22 | F42: extra | L42: ok
A47: CODECLIENT | B47: PaiementsCBSite | E47: Montant | F47: Remarques | L47: SAP
A48: c3051 | B48: premierfood | E48: 228.17 | L48: ok
B49: stephanedelalande | E49: 348.06 | F49: 345.87 | G49: 2.19 | H49: paypal+cash | L49: ok
A50: c7738 | B50: ISIA | E50: 596.21 | F50: extra | L50: ok
...

Sheet 8
I1: DATE | J1: 46120
G2: no002802554130
E3: RemiseBancaire(SAP) | G3: no002802754215 | I3: EXCEL
E4: Espèces | F4: 10205 | G4: no002802601860 | I4: ESPECES | K4: =E82+C14 -> 10206.6
E5: Chèques | F5: 4772.85 | G5: no94772,85 | I5: CHEQUES | K5: =E15+E83 -> 4772.85
E6: Monnaienondéposée | F6: 1.7 | I6: CARTECREDIT | K6: =G15+E84 -> 24660.95
I7: VIREMENT | K7: =SUM(E59:E64) -> 0
B8: CaisseEspèces | D8: Caissechèques | F8: CaisseCB
B9: Billetsde50 | C9: 3250 | D9: Client | E9: Montant | F9: Client | G9: Montant | I9: Dépenses:Essence,Divers | L9: Montant
B10: Billetsde20 | C10: 2640 | D10: alishanrest | E10: 492.33 | F10: Till | G10: 24660.95 | I10: SAMIRGASOIL | L10: 300
B11: Billetsde10 | C11: 2600 | D11: maxchic | E11: 743.17 | F11: sancont | I11: AHMEDGASOIL | L11: 80
B12: Billetsde5 | C12: 225 | I12: SKANDERGASOIL(RENDU) | L12: 80
B13: Monnaie | I13: rembursmentclient | L13: 34.8
B14: Total | C14: =SUM(C9:C13) -> 8715 | I14: ahmedpeage | L14: 3.8
B15: Fonddecaisse | C15: 366 | D15: Total | E15: =SUM(E10:E14) -> 1235.5 | F15: Total | G15: =SUM(G10:G14) -> 24660.95 | I15: DifférenceFondCaisse | L15: =C15-'7'!C15 -> -85
K16: Total | L16: =(SUM(L10:L15))*-1 -> -413.6
A18: LIVRAISONS
A19: CODECLIENT | B19: PaiementsChèques | E19: Montant | F19: Banque | G19: Numero | H19: Remarques | L19: SAP
A20: C1373 | B20: SARLWANOBI | E20: 291.91 | F20: SG | G20: 3597 | L20: OK
A21: C5144 | B21: MCVFAIDHERBE | E21: 465.96 | F21: BRED | G21: 7051121 | L21: OK
A22: C5144 | B22: MCVFAIDHERBE | E22: 467.46 | F22: BRED | G22: 7051122 | H22: ANCIENPAIEMENT | L22: OK
A23: C1222 | B23: RELAISD'OR | E23: 461.41 | F23: CIC | G23: 2569200 | L23: OK
A24: C5316 | B24: PIZZERIAVIVALDI | E24: 363.45 | F24: CIC | G24: 3684538 | L24: OK
A25: C6212 | B25: EURLHE | E25: 549.34 | F25: CIC | G25: 8309673 | L25: OK
A26: C4602 | B26: CHAMAS | E26: 937.82 | F26: CIC | G26: 3885361 | L26: OK
A38: CODECLIENT | B38: PaiementsEspèces | E38: Montant | F38: Remarques | L38: SAP
A39: C7735 | B39: RAPIDEFOOD | E39: 450.7 | L39: OK
A40: C9999 | B40: VCCROUSTYFAMILY | E40: 960.9 | L40: OK
B41: RETOURGASOILSKANDER | E41: 80
A48: CODECLIENT | B48: PaiementsCBSite | E48: Montant | F48: Remarques | L48: SAP
A53: CODECLIENT | B53: PaiementsCBTéléphone | E53: Montant | F53: Remarques | L53: SAP
C54: 802.36 | D54: cari versailles
C55: 675.28 | D55: cqfd
C56: 689.72 | D56: cqfd
C57: 340.26 | D57: new
A58: CODECLIENT | B58: Virements | E58: Montant | F58: Remarques | L58: SAP
A65: CODECLIENT | B65: Livraisonsnonpayées | E65: Montant | F65: Remarques | L65: SAP
A66: C5842 | B66: GARBACHAUD | E66: 399.47 | L66: OK
A67: C1971 | B67: ESCOMPANY | E67: 520.62 | L67: OK
A68: C5877 | B68: ANOUAR | E68: 968.16 | L68: OK
...

Sheet 9
I1: DATE | J1: 46121
E3: RemiseBancaire(SAP) | G3: no002802354345 | I3: EXCEL
E4: Espèces | F4: 9085 | G4: no002802404740 | I4: ESPECES | K4: =E90+C14 -> 9089.25
E5: Chèques | F5: 3332.54 | G5: no93332,54 | I5: CHEQUES | K5: =E15+E91 -> 3332.54
E6: Monnaienondéposée | F6: 4.25 | I6: CARTECREDIT | K6: =G15+E92 -> 14803.5
I7: VIREMENT | K7: =SUM(E59:E64) -> 0
B8: CaisseEspèces | D8: Caissechèques | F8: CaisseCB
B9: Billetsde50 | C9: 2900 | D9: Client | E9: Montant | F9: Client | G9: Montant | I9: Dépenses:Essence,Divers | L9: Montant
B10: Billetsde20 | C10: 2020 | D10: alishan | E10: 233.74 | F10: Till | G10: 18255.95 | I10: skandergasoil | L10: 80
B11: Billetsde10 | C11: 2320 | D11: ausundine | E11: 357.04 | F11: sancont | I11: samirgasoil | L11: 70
B12: Billetsde5 | C12: 125 | F12: sobicashextra | G12: 2700
B13: Monnaie | F13: sobicashextra | G13: 752.45
B14: Total | C14: =SUM(C9:C13) -> 7365
B15: Fonddecaisse | C15: 488 | D15: Total | E15: =SUM(E10:E14) -> 590.78 | F15: Total | G15: =SUM(G10-G12-G13)+G11 -> 14803.5 | I15: DifférenceFondCaisse | L15: =C15-'8'!C15 -> 122
K16: Total | L16: =(SUM(L10:L15))*-1 -> -272
A18: LIVRAISONS
A19: CODECLIENT | B19: PaiementsChèques | E19: Montant | F19: Banque | G19: Numero | H19: Remarques | L19: SAP
A20: c6508 | B20: RannouchExpress | E20: 506.27 | F20: bnp | G20: 1681099 | L20: ok
A21: c7142 | B21: CHEZMIMI | E21: 301.31 | F21: bnp | G21: 7642072 | L21: ok
A22: c4215 | B22: BOULANGERIECAJAN | E22: 598.02 | F22: bp | G22: 113 | L22: ok
A23: c7619 | B23: BrahimChammakhi | E23: 324.13 | F23: lcl | G23: 2441412 | L23: ok
A24: c5355 | B24: RedhaDJAMA | E24: 294.79 | F24: lcl | G24: 654799 | L24: ok
B25: SarlCdr | E25: 415.78 | F25: bp | G25: 255 | L25: ok
A26: c1526 | B26: SUSHIYAKI | E26: 301.46 | F26: cic | G26: 1208973
A38: CODECLIENT | B38: PaiementsEspèces | E38: Montant | F38: Remarques | L38: SAP
A39: c6114 | B39: sobicash | E39: 1000 | F39: enlevementsurplace | L39: ok
A40: c3017 | B40: PFCARDINET(MATHIEUBoulangerie) | E40: 403.1 | L40: ok
A41: c7753 | B41: BENAYADMOHAMED | E41: 321.15 | L41: ok
A48: CODECLIENT | B48: PaiementsCBSite | E48: Montant | F48: Remarques | L48: SAP
A53: CODECLIENT | B53: PaiementsCBTéléphone | E53: Montant | F53: Remarques | L53: SAP
C54: 802.36 | D54: cari versailles
C55: 675.28 | D55: cqfd
C56: 689.72 | D56: cqfd
C57: 340.26 | D57: new
A58: CODECLIENT | B58: Virements | E58: Montant | F58: Remarques | L58: SAP
A65: CODECLIENT | B65: Livraisonsnonpayées | E65: Montant | F65: Remarques | L65: SAP
A66: c5431 | B66: DreamFactory | E66: 303.08 | L66: ok
A67: c6004 | B67: NEWSOULFOOD | E67: 443.1 | L67: ok
A68: c6367 | B68: SARLLACREPESURMESURE | E68: 1121.67 | L68: ok
A69: c3127 | B69: moustacheetfils | E69: 1760.97 | L69: ok
...

Sheet 11
I1: DATE | J1: 46123
G2: no002801986490
E3: RemiseBancaire(SAP) | G3: no002801832000 | I3: EXCEL
E4: Espèces | F4: 13690 | G4: no002802005200 | I4: ESPECES | K4: =E80+C14 -> 13690
E5: Chèques | F5: 1582.95 | G5: no31582,95 | I5: CHEQUES | K5: =E15+E81 -> 1582.95
E6: Monnaienondéposée | I6: CARTECREDIT | K6: =G15+E82 -> 22365.06
I7: VIREMENT | K7: =SUM(E59:E64) -> 0
B8: CaisseEspèces | D8: Caissechèques | F8: CaisseCB
B9: Billetsde50 | C9: 5000 | D9: Client | E9: Montant | F9: Client | G9: Montant | I9: Dépenses:Essence,Divers | L9: Montant
B10: Billetsde20 | C10: 5200 | D10: buffetgare | E10: 744.8 | F10: Till | G10: 22365.06 | I10: skandergasoil | L10: 80
B11: Billetsde10 | C11: 3490 | D11: lbf | E11: 339.88 | F11: sancont | I11: skandersamdi | L11: 260
B12: Billetsde5 | D12: alishanrest | E12: 498.27 | I12: houcinegasoil | L12: 80
B13: Monnaie | I13: ahmedgasoil | L13: 80
B14: Total | C14: =SUM(C9:C13) -> 13690
B15: Fonddecaisse | C15: 412 | D15: Total | E15: =SUM(E10:E14) -> 1582.95 | F15: Total | G15: =SUM(G10:G14) -> 22365.06 | I15: DifférenceFondCaisse | L15: =C15-'10'!C15 -> -28
K16: Total | L16: =(SUM(L10:L15))*-1 -> -472
A18: LIVRAISONS
A19: CODECLIENT | B19: PaiementsChèques | E19: Montant | F19: Banque | G19: Numero | H19: Remarques | L19: SAP
A38: CODECLIENT | B38: PaiementsEspèces | E38: Montant | F38: Remarques | L38: SAP
A48: CODECLIENT | B48: PaiementsCBSite | E48: Montant | F48: Remarques | L48: SAP
A53: CODECLIENT | B53: PaiementsCBTéléphone | E53: Montant | F53: Remarques | L53: SAP
C54: 802.36 | D54: cari versailles
C55: 675.28 | D55: cqfd
C56: 689.72 | D56: cqfd
C57: 340.26 | D57: new
A58: CODECLIENT | B58: Virements | E58: Montant | F58: Remarques | L58: SAP
A65: CODECLIENT | B65: Livraisonsnonpayées | E65: Montant | F65: Remarques | L65: SAP
B80: TOTALESPECES | E80: =SUM(E39:E47) -> 0
B81: TOTALCHEQUES | E81: =SUM(E20:E37) -> 0
B82: TOTALCBInternet&Phone | E82: =SUM(E49:E57) -> 0

Sheet 10
I1: DATE | J1: 46122
E3: RemiseBancaire(SAP) | G3: no002802204440 | I3: EXCEL
E4: Espèces | F4: 6710 | G4: no002802152270 | I4: ESPECES | K4: =E103+C14 -> 6717.7
E5: Chèques | F5: 4120.46 | G5: no106723,37 | I5: CHEQUES | K5: =E15+E104 -> 6723.37
E6: Monnaienondéposée | F6: 7.7 | I6: CARTECREDIT | K6: =G15+E105 -> 26138.03
I7: VIREMENT | K7: =SUM(E68:E73) -> 0
B8: CaisseEspèces | D8: Caissechèques | F8: CaisseCB
B9: Billetsde50 | C9: 2000 | D9: Client | E9: Montant | F9: Client | G9: Montant | I9: Dépenses:Essence,Divers | L9: Montant
B10: Billetsde20 | C10: 1940 | D10: alishanrest | E10: 309.49 | F10: Till | G10: 15955.55 | I10: ahmed | L10: 80
B11: Billetsde10 | C11: 2270 | F11: sancont | I11: samir | L11: 80
B12: Billetsde5 | C12: 30 | I12: skander | L12: 80
B13: Monnaie
B14: Total | C14: =SUM(C9:C13) -> 6240
B15: Fonddecaisse | C15: 440 | D15: Total | E15: =SUM(E10:E14) -> 309.49 | F15: Total | G15: =SUM(G10:G14) -> 15955.55 | I15: DifférenceFondCaisse | L15: =C15-'9'!C15 -> -48
K16: Total | L16: =(SUM(L10:L15))*-1 -> -192
A18: LIVRAISONS
A19: CODECLIENT | B19: PaiementsChèques | E19: Montant | F19: Banque | G19: Numero | H19: Remarques | L19: SAP
B20: HOTPIZZA77 | E20: 347 | F20: CIC | G20: 6361484 | L20: OK
A21: c7615 | B21: zaheralkhubi | E21: 575.61 | F21: lcl | G21: 3260692 | L21: ok
A22: c5052 | B22: RESTOBEYROUTH | E22: 356.36 | F22: sg | G22: 2000424 | L22: ok
A23: c6707 | B23: ShaziaBaig | E23: 642.68 | F23: bnp | G23: 2650137 | L23: ok
A24: c5004 | B24: RobertAsseraf | E24: 639.15 | F24: sg | G24: 891 | L24: ok
A25: c3757 | B25: SASTHON | E25: 280.39 | F25: lcl | G25: 9334224 | L25: ok
A26: c3476 | B26: VICTORIA168 | E26: 689.38 | F26: sg | G26: 299 | L26: ok
A27: c2938 | B27: MCVDumas | E27: 280.4 | F27: bred | G27: 8738421 | L27: ok
B28: EXTRASARLSTEABRAJ | E28: 2602.91
A38: CODECLIENT | B38: PaiementsEspèces | E38: Montant | F38: Remarques | L38: SAP
B39: skander | E39: 80 | F39: retourgasoil
A40: c3888 | B40: CHICKENHOTETPIZZA | E40: 3.72 | F40: extra | L40: ok
A41: c5702 | B41: FahadMuhammad | E41: 393.98 | L41: ok
A48: CODECLIENT | B48: PaiementsCBSite | E48: Montant | F48: Remarques | L48: SAP
A53: CODECLIENT | B53: PaiementsCBTéléphone | E53: Montant | F53: Remarques | L53: SAP
A54: C7396 | B54: LESSAVEURSDEGRETZ | C54: 802.36 | D54: cari versailles | E54: 388.44 | L54: OK
A55: C6534 | C55: DEDAMASABEYROUTH | E55: 347.01 | L55: OK
A56: C6446 | C56: LEBNEN | E56: 300 | L56: OK
A57: c7737 | C57: SARLPESNEL | E57: 966.56 | L57: ok
A58: C4202 | C58: LAFRAICHEUR | E58: 3338.67 | L58: OK
A59: C5716 | C59: GIEMF | E59: 4288.15 | L59: OK
A60: C7604 | C60: maximestefanos | E60: 553.65 | L60: OK
C64: 675.28 | D64: cqfd
...

Sheet 13
I1: DATE | J1: 46125
E3: RemiseBancaire(SAP) | G3: no002797563480 | I3: EXCEL
E4: Espèces | F4: 8140 | G4: no00280784660 | I4: ESPECES | K4: =E233+C14 -> 8149.22
E5: Chèques | F5: 5447.35 | G5: no135447,35 | I5: CHEQUES | K5: =E15+E234 -> 5447.35
E6: Monnaienondéposée | F6: 9.42 | I6: CARTECREDIT | K6: =G15+E235 -> 19299.85
I7: VIREMENT | K7: =SUM(E59:E209) -> 293540.43
B8: CaisseEspèces | D8: Caissechèques | F8: CaisseCB
B9: Billetsde50 | C9: 2750 | D9: Client | E9: Montant | F9: Client | G9: Montant | I9: Dépenses:Essence,Divers | L9: Montant
B10: Billetsde20 | C10: 2020 | D10: ausundine | E10: 821.3 | F10: Till | G10: 19299.85 | I10: samirgasoil | L10: 80
B11: Billetsde10 | C11: 1460 | D11: alishanrest | E11: 571.51 | F11: sancont | I11: ahmedgasoil | L11: 80
B12: Billetsde5 | C12: 185 | I12: ahmedpeage | L12: 3.8
B13: Monnaie | I13: houcineacompte | L13: 140
B14: Total | C14: =SUM(C9:C13) -> 6415 | I14: acompteyahya | L14: 345
B15: Fonddecaisse | C15: 374 | D15: Total | E15: =SUM(E10:E14) -> 1392.81 | F15: Total | G15: =SUM(G10:G14) -> 19299.85 | I15: DifférenceFondCaisse | L15: =C15-'11'!C15 -> -38
K16: Total | L16: =(SUM(L10:L15))*-1 -> -610.8
A18: LIVRAISONS
A19: CODECLIENT | B19: PaiementsChèques | E19: Montant | F19: Banque | G19: Numero | H19: Remarques | L19: SAP
A20: c6940 | B20: mcvlavillette | E20: 327.78 | F20: sg | G20: 75 | L20: ok
A21: c6881 | B21: lapyramide | E21: 498.04 | F21: lcl | G21: 2232938 | L21: ok
A22: c1640 | B22: ancreperie | E22: 259.85 | F22: bnp | G22: 6704518 | H22: ancienpaiement | L22: ok
A23: c6431 | B23: pandaexpress | E23: 307.81 | F23: cic | G23: 3944333 | L23: ok
A24: c4168 | B24: kchimaek | E24: 282.6 | F24: bnp | G24: 9427107 | L24: ok
A25: c4494 | B25: mcvdaumesnil | E25: 270.89 | F25: bred | G25: 8622365 | L25: ok
A26: c4492 | B26: masmaris | E26: 322.62 | F26: cic | G26: 3895400 | L26: ok
A27: c1465 | B27: delicedebeyrouth | E27: 681.13 | F27: sg | G27: 3000484 | L27: ok
A28: c3476 | B28: victoria168 | E28: 573.41 | F28: sg | G28: 300 | L28: ok
A29: c6470 | B29: rannouch | E29: 304.68 | F29: bnp | G29: 1681133 | L29: ok
A30: c4548 | B30: cotepigalle | E30: 225.73 | F30: bpop | G30: 494 | L30: ok
A38: CODECLIENT | B38: PaiementsEspèces | E38: Montant | F38: Remarques | L38: SAP
A39: c3469 | B39: boulangeriemehdaoui | E39: 692.85 | L39: ok
A40: c6330 | B40: adnan | E40: 120.5 | L40: ok
A41: c4031 | B41: lewarner | E41: 304.44 | L41: ok
B42: extran-c-f | E42: 616.43 | L42: ok
A48: CODECLIENT | B48: PaiementsCBSite | E48: Montant | F48: Remarques | L48: SAP
A53: CODECLIENT | B53: PaiementsCBTéléphone | E53: Montant | F53: Remarques | L53: SAP
C54: 802.36 | D54: cari versailles
C55: 675.28 | D55: cqfd
C56: 689.72 | D56: cqfd
C57: 340.26 | D57: new
A58: CODECLIENT | B58: Virements | E58: Montant | F58: Remarques | L58: SAP
...

Sheet 14
G1: no002797962000 | I1: DATE | J1: 46126
G2: no002797762190
E3: RemiseBancaire(SAP) | G3: no002797614200 | I3: EXCEL
E4: Espèces | F4: 10170 | G4: no002797811780 | I4: ESPECES | K4: =E198+C17 -> 10174.53
E5: Chèques | F5: 2324.01 | G5: no32324,01 | I5: CHEQUES | K5: =E18+E199 -> 2324.01
E6: Monnaienondéposée | F6: 4.53 | I6: CARTECREDIT | K6: =G18+E200 -> 18118.33
I7: VIREMENT | K7: =SUM(E62:E174) -> 244293.16
B8: CaisseEspèces | D8: Caissechèques | F8: CaisseCB
B9: Billetsde50 | C9: 1700 | D9: Client | E9: Montant | F9: Client | G9: Montant | I9: Dépenses:Essence,Divers | L9: Montant
B10: Billetsde20 | C10: 2220 | D10: alishanrest | E10: 275.87 | F10: Till | G10: 18118.33 | I10: HOCINEGASOIL | L10: 80
B11: Billetsde10 | C11: 5970 | F11: sancont | I11: SKANDERGASOIL | L11: 80
I12: ZOUHIRACOMPTE | L12: 170
I13: YAHYARENDUARGENT | L13: 141
I14: SONIAACOMPTE | L14: 720
B15: Billetsde5 | C15: 190 | I15: SAMIRGASOIL | L15: 200
B16: Monnaie | I16: ABUBAKARGASOIL | L16: 80
B17: Total | C17: =SUM(C9:C16) -> 10080 | I17: AHMEDACOMPTE | L17: 390
B18: Fonddecaisse | C18: 317 | D18: Total | E18: =SUM(E10:E17) -> 275.87 | F18: Total | G18: =SUM(G10:G17) -> 18118.33 | I18: DifférenceFondCaisse | L18: =C18-'13'!C15 -> -57
K19: Total | L19: =(SUM(L10:L18))*-1 -> -1804
A21: LIVRAISONS
A22: CODECLIENT | B22: PaiementsChèques | E22: Montant | F22: Banque | G22: Numero | H22: Remarques | L22: SAP
A23: C6940 | B23: MCVLAVILLETTE | E23: 322.51 | F23: SG | G23: 76 | L23: OK
A24: C3186 | B24: VIFZAEKA | E24: 1725.63 | F24: CIC | G24: 3044072 | L24: OK
A41: CODECLIENT | B41: PaiementsEspèces | E41: Montant | F41: Remarques | L41: SAP
A42: C6159 | B42: ROSMINS | E42: 94.53 | F42: ANCIENPAIEMENT | L42: OK
A51: CODECLIENT | B51: PaiementsCBSite | E51: Montant | F51: Remarques | L51: SAP
A56: CODECLIENT | B56: PaiementsCBTéléphone | E56: Montant | F56: Remarques | L56: SAP
C57: 802.36 | D57: cari versailles
C58: 675.28 | D58: cqfd
C59: 689.72 | D59: cqfd
C60: 340.26 | D60: new
A61: CODECLIENT | B61: Virements | E61: Montant | F61: Remarques | L61: SAP
B62: S,A,S,HETNMARKET | E62: 284.5 | L62: ok
B63: CHICKENASIA | E63: 125.96 | L63: ok
B64: CHICKENSPOT | E64: 232.63 | L64: ok
B65: SUSHIBOX | E65: 315.68 | L65: ok
B66: SARLBKK1 | E66: 316.87 | L66: ok
B67: LEFKA | E67: 737.29 | L67: ok
B68: SASTENDERSBROTHERS | E68: 1047.27 | L68: ok
B69: S,A,R,L,LAFRITEDUNORD | E69: 438.66 | L69: ok
...

Sheet 15
I1: DATE | J1: 46127
E3: RemiseBancaire(SAP) | G3: no002798132130 | I3: EXCEL
E4: Espèces | F4: 6900 | G4: no002798084770 | I4: ESPECES | K4: =E287+C14 -> 6905.92
E5: Chèques | F5: 4466.21 | G5: no104466,21 | I5: CHEQUES | K5: =E15+E288 -> 4466.21
E6: Monnaienondéposée | F6: 6 | I6: CARTECREDIT | K6: =G15+E289 -> 64535.96
I7: VIREMENT | K7: =SUM(E115:E256) -> 354933.52
B8: CaisseEspèces | D8: Caissechèques | F8: CaisseCB
B9: Billetsde50 | C9: 1550 | D9: Client | E9: Montant | F9: Client | G9: Montant | I9: Dépenses:Essence,Divers | L9: Montant
B10: Billetsde20 | C10: 1780 | D10: alishanrest | E10: 498.3 | F10: Till | G10: 19899.16 | I10: ahmedpeage | L10: 3.8
B11: Billetsde10 | C11: 2130 | D11: lemeraude | E11: 596.18 | F11: sancont
B12: Billetsde5 | C12: 60
B13: Monnaie
B14: Total | C14: =SUM(C9:C13) -> 5520
B15: Fonddecaisse | C15: 276 | D15: Total | E15: =SUM(E10:E14) -> 1094.48 | F15: Total | G15: =SUM(G10:G14) -> 19899.16 | I15: DifférenceFondCaisse | L15: =C15-'14'!C18 -> -41
K16: Total | L16: =(SUM(L10:L15))*-1 -> 37.2
A18: LIVRAISONS
A19: CODECLIENT | B19: PaiementsChèques | E19: Montant | F19: Banque | G19: Numero | H19: Remarques | L19: SAP
A20: C4647 | B20: TAMKINE | E20: 234.51 | F20: CM | G20: 6375623 | L20: OK
A21: C7212 | B21: HUGOGAO | E21: 448.11 | F21: CE | G21: 473 | L21: OK
A22: C3476 | B22: VICTORIA168 | E22: 360.69 | F22: SG | G22: 301 | L22: OK
A23: C5144 | B23: MCVFAIDHERBE | E23: 341.5 | F23: BRED | G23: 7051123 | L23: OK
A24: C4168 | B24: KCHIMAEK | E24: 272.06 | F24: BNP | G24: 9427108 | L24: OK
A25: C1376 | B25: DELICEHOUSE | E25: 392.07 | F25: CE | G25: 9978480 | L25: OK
A26: C6676 | B26: HUGOGAO | E26: 293.06 | F26: BNP | G26: 2640913 | L26: OK
A27: C3942 | B27: SASLATIF | E27: 1029.73 | F27: BPOP | G27: 104 | L27: OK
A38: CODECLIENT | B38: PaiementsEspèces | E38: Montant | F38: Remarques | L38: SAP
A39: C9999 | B39: VCCROUSTYFAMILY | E39: 959.69 | L39: OK
A40: C3017 | B40: PFBABYLONE | E40: 426.23 | L40: OK
A48: CODECLIENT | B48: PaiementsCBSite | E48: Montant | F48: Remarques | L48: SAP
B49: 12/03/2026PaiementDCC:SodaryKHAMPRASEUTHTerminé | E49: 357.6 | F49: 2.25 | G49: 355.35 | H49: paypal+cash | L49: ok
B50: 12/03/2026PaiementExpressCheckout:faridboudiharTerminé | E50: 1992.57 | F50: 40.1 | G50: 1952.47 | H50: paypal+cash | L50: ok
B51: 12/03/2026PaiementDCC:ThiNhatHaNGUYENTerminé | E51: 331.15 | F51: 2.09 | G51: 329.06 | H51: paypal+cash | L51: ok
B52: 14/03/2026PaiementExpressCheckout:NinaMetoudiTerminé | E52: 377.3 | F52: 7.8 | G52: 369.5 | H52: paypal+cash | L52: ok
B53: 15/03/2026PaiementDCC:PascalPapillonTerminé | E53: 335.61 | F53: 2.11 | G53: 333.5 | H53: paypal+cash | L53: ok
B54: 15/03/2026PaiementDCC:SASToliaTerminé | E54: 333.91 | F54: 2.1 | G54: 331.81 | H54: paypal+cash | L54: ok
B55: PaiementDCC:LESMARMITESDECATHY 16/03/2026PEROZZIELLOAlexandreTerminé | E55: 847.72 | F55: 5.19 | G55: 842.53 | H55: paypal+cash | L55: ok
B56: 16/03/2026PaiementDCC:VaughnJanesTerminé | E56: 354.93 | F56: 2.23 | G56: 352.7 | H56: paypal+cash | L56: ok
B57: 16/03/2026PaiementExpressCheckout:akramchammamTerminé | E57: 590.42 | F57: 12.06 | G57: 578.36 | H57: paypal+cash | L57: ok
B58: 17/03/2026PaiementDCC:GolamAzamTerminé | E58: 337.51 | F58: 2.13 | G58: 335.38 | H58: paypal+cash | L58: ok
B59: 17/03/2026PaiementExpressCheckout:AnélineCayezTerminé | E59: 995.04 | F59: 20.15 | G59: 974.89 | H59: paypal+cash | L59: ok
...

Sheet 16
I1: DATE | J1: 46129
E3: RemiseBancaire(SAP) | G3: no002798335295 | I3: EXCEL
E4: Espèces | F4: 7485 | G4: no002798282190 | I4: ESPECES | K4: =E154+C14 -> 7489.95
E5: Chèques | F5: 5871.81 | G5: no75871,81 | I5: CHEQUES | K5: =E15+E155 -> 5871.81
E6: Monnaienondéposée | F6: 4.95 | I6: CARTECREDIT | K6: =G15+E156 -> 95422.85
I7: VIREMENT | K7: =SUM(E129:E138) -> 0
B8: CaisseEspèces | D8: Caissechèques | F8: CaisseCB
B9: Billetsde50 | C9: 2950 | D9: Client | E9: Montant | F9: Client | G9: Montant | I9: Dépenses:Essence,Divers | L9: Montant
B10: Billetsde20 | C10: 2280 | D10: maxchicken | E10: 584.86 | F10: Till | G10: 23215.07 | I10: SAMIR | L10: 80
B11: Billetsde10 | C11: 1560 | D11: ausundine | E11: 296.21 | F11: sancont | I11: skandargasoil | L11: 70
B12: Billetsde5 | C12: 65 | I12: ahmedgasoil | L12: 40
B13: Monnaie | I13: abubakarrestsalarymars2026 | L13: 100
B14: Total | C14: =SUM(C9:C13) -> 6855 | I14: ahmed | L14: 20
B15: Fonddecaisse | C15: 250 | D15: Total | E15: =SUM(E10:E14) -> 881.07 | F15: Total | G15: =SUM(G10:G14) -> 23215.07 | I15: DifférenceFondCaisse | L15: =C15-'15'!C15 -> -26
K16: Total | L16: =(SUM(L10:L15))*-1 -> -284
A18: LIVRAISONS
A19: CODECLIENT | B19: PaiementsChèques | E19: Montant | F19: Banque | G19: Numero | H19: Remarques | L19: SAP
A20: C7452 | B20: MARKETDEPOTPSB | E20: 2792.16 | F20: CAIXAGERAL | G20: 5761216 | H20: EXTRASURPLACE | L20: OK
A21: C1541 | B21: SarlCdr | E21: 270.83 | F21: BP | G21: 6383 | L21: OK
A22: c3063 | B22: SASUZOYA | E22: 174.5 | F22: bp | G22: 660 | L22: ok
A23: c3757 | B23: SASTHON | E23: 1411.27 | F23: lcl | G23: 933427 | L23: ok
A24: c6508 | B24: RannouchExpress | E24: 341.98 | F24: bnp | G24: 1681100 | L24: ok
A38: CODECLIENT | B38: PaiementsEspèces | E38: Montant | F38: Remarques | L38: SAP
A39: c5527 | B39: SNCTABACDUTROCADERO | E39: 332.63 | L39: ok
A40: c7735 | B40: RAPIDEFOOD | E40: 260 | L40: ok
A41: c0993 | B41: CAPPADOCE | E41: 42.32 | F41: EXTRA | L41: ok
A48: CODECLIENT | B48: PaiementsCBSite | E48: Montant | F48: Remarques | L48: SAP
B49: 12/03/2026 Paiement DCC: Sodary KHAMPRASEUTH Terminé | E49: 357.6 | F49: 2.25 | G49: 355.35 | H49: paypal + cash
B50: 12/03/2026 Paiement Express Checkout: farid boudihar Terminé | E50: 1992.57 | F50: 40.1 | G50: 1952.47 | H50: paypal + cash
B51: 12/03/2026 Paiement DCC: Thi Nhat Ha NGUYEN Terminé | E51: 331.15 | F51: 2.09 | G51: 329.06 | H51: paypal + cash
B52: 14/03/2026 Paiement Express Checkout: Nina Metoudi Terminé | E52: 377.3 | F52: 7.8 | G52: 369.5 | H52: paypal + cash
B53: 15/03/2026 Paiement DCC: Pascal Papillon Terminé | E53: 335.61 | F53: 2.11 | G53: 333.5 | H53: paypal + cash
B54: 15/03/2026 Paiement DCC: SAS Tolia Terminé | E54: 333.91 | F54: 2.1 | G54: 331.81 | H54: paypal + cash
B55: Paiement DCC: LES MARMITES DE CATHY 16/03/2026 PEROZZIELLO Alexandre Terminé | E55: 847.72 | F55: 5.19 | G55: 842.53 | H55: paypal + cash
B56: 16/03/2026 Paiement DCC: Vaughn Janes Terminé | E56: 354.93 | F56: 2.23 | G56: 352.7 | H56: paypal + cash
B57: 16/03/2026 Paiement Express Checkout: akram chammam Terminé | E57: 590.42 | F57: 12.06 | G57: 578.36 | H57: paypal + cash
B58: 17/03/2026 Paiement DCC: Golam Azam Terminé | E58: 337.51 | F58: 2.13 | G58: 335.38 | H58: paypal + cash
B59: 17/03/2026 Paiement Express Checkout: Anéline Cayez Terminé | E59: 995.04 | F59: 20.15 | G59: 974.89 | H59: paypal + cash
B60: 18/03/2026 Paiement DCC: Akbar Khan Terminé | E60: 467.24 | F60: 2.9 | G60: 464.34 | H60: paypal + cash
... B105: 11/04/2026 Paiement DCC: Maxime Rivat Terminé | E105: 2081.98 | F105: 12.59 | G105: 2069.39 | H105: paypal + cash
...

Sheet 17
I1: DATE | J1: 46129
E3: RemiseBancaire(SAP) | I3: EXCEL
E4: Espèces | F4: 3735 | G4: no002798533735 | I4: ESPECES | K4: =E89+C14 -> 3734.24
E5: Chèques | F5: 14073.27 | G5: no1514073,27 | I5: CHEQUES | K5: =E15+E90 -> 14073.27
E6: Monnaienondéposée | F6: 9.24 | I6: CARTECREDIT | K6: =G15+E91 -> 16803.8
I7: VIREMENT | K7: =SUM(E59:E64) -> 0
B8: CaisseEspèces | D8: Caissechèques | F8: CaisseCB
B9: Billetsde50 | C9: 800 | D9: Client | E9: Montant | F9: Client | G9: Montant | I9: Dépenses:Essence,Divers | L9: Montant
B10: Billetsde20 | C10: 1520 | D10: alishanrest | E10: 559.87 | F10: Till | G10: 16803.8 | I10: abubakargasoil351camionlivraisin | L10: 80
B11: Billetsde10 | C11: 1190 | F11: sancont | I11: remboursmentgasoilyahya | L11: 70
B12: Billetsde5 | C12: 215 | I12: idreessb | L12: 1000
B13: Monnaie
B14: Total | C14: =SUM(C9:C13) -> 3725
B15: Fonddecaisse | C15: 291 | D15: Total | E15: =SUM(E10:E14) -> 559.87 | F15: Total | G15: =SUM(G10:G14) -> 16803.8 | I15: DifférenceFondCaisse | L15: =C15-'16'!C15 -> 41
K16: Total | L16: =(SUM(L10:L15))*-1 -> -1191
A18: LIVRAISONS
A19: CODECLIENT | B19: PaiementsChèques | E19: Montant | F19: Banque | G19: Numero | H19: Remarques | L19: SAP
A20: c4517 | B20: etoile(18eme) | E20: 1783.53 | F20: lcl | G20: 7340557 | L20: ok
A21: c6171 | B21: SarlTAMASINI | E21: 706.43 | F21: bnp | G21: 8903628 | L21: ok
A22: c7664 | B22: RestaurantCheezy | E22: 558.09 | F22: bnp | G22: 2693024 | L22: ok
A23: c6482 | B23: RannouchCity | E23: 552.23 | F23: bnp | G23: 1681014 | L23: ok
A24: c4215 | B24: BOULANGERIECAJAN | E24: 450.39 | F24: bp | G24: 114 | L24: ok
A25: c3476 | B25: VICTORIA168 | E25: 329.39 | F25: sg | G25: 302 | L25: ok
A26: c1971 | B26: ESCOMPANY | E26: 466.74 | F26: bp | G26: 4486 | L26: ok
A27: c1971 | B27: ESCOMPANY | E27: 520.62 | F27: bp | G27: 4485 | L27: ok
A28: c6940 | B28: MCVLAVILLETTE | E28: 416.84 | F28: sg | G28: 77 | L28: ok
A29: c1513 | B29: EDENDI | E29: 4549.22 | F29: sg | G29: 475 | L29: ok
A30: c4602 | B30: chamastacosguerrida | E30: 992.66 | F30: cic | G30: 3885377 | L30: ok
A31: c4650 | B31: BREADSHOP | E31: 746.85 | F31: bp | G31: 2371 | L31: ok
... A33: c1547 | B33: ANATOLIEN | E33: 873.96 | F33: bp | G33: 9788455 | L33: ok
A38: CODECLIENT | B38: PaiementsEspèces | E38: Montant | F38: Remarques | L38: SAP
E39: 9.24 | F39: retourgasoilaboubaker
A48: CODECLIENT | B48: PaiementsCBSite | E48: Montant | F48: Remarques | L48: SAP
A49: C7161 | B49: SOIXANTE ET ONZE | F49: extra2044,54 | L49: OK
A53: CODECLIENT | B53: PaiementsCBTéléphone | E53: Montant | F53: Remarques | L53: SAP
C54: 802.36 | D54: cari versailles
C55: 675.28 | D55: cqfd
C56: 689.72 | D56: cqfd
C57: 340.26 | D57: new
A58: CODECLIENT | B58: Virements | E58: Montant | F58: Remarques | L58: SAP
...

Sheet 18
I1: DATE | J1: 46130
G2: no002798881880
E3: RemiseBancaire(SAP) | G3: no002798686420 | I3: EXCEL
E4: Espèces | F4: 10145 | G4: no002798731845 | I4: ESPECES | K4: =E80+C14 -> 10145
E5: Chèques | F5: 2597.37 | G5: no42597,37 | I5: CHEQUES | K5: =E15+E81 -> 2597.37
E6: Monnaienondéposée | I6: CARTECREDIT | K6: =G15+E82 -> 29315.67
I7: VIREMENT | K7: =SUM(E59:E64) -> 0
B8: CaisseEspèces | D8: Caissechèques | F8: CaisseCB
B9: Billetsde50 | C9: 3200 | D9: Client | E9: Montant | F9: Client | G9: Montant | I9: Dépenses:Essence,Divers | L9: Montant
B10: Billetsde20 | C10: 3220 | D10: 3afoods | E10: 423.6 | F10: Till | G10: 29315.67 | I10: hocinegasoil | L10: 80
B11: Billetsde10 | C11: 3580 | D11: buffetgare | E11: 805.26 | F11: sancont | I11: samirgasoiladblu | L11: 232
B12: Billetsde5 | C12: 145 | D12: leforentin | E12: 802.43
B13: Monnaie | D13: alishanrest | E13: 566.08
B14: Total | C14: =SUM(C9:C13) -> 10145
B15: Fonddecaisse | C15: 253 | D15: Total | E15: =SUM(E10:E14) -> 2597.37 | F15: Total | G15: =SUM(G10:G14) -> 29315.67 | I15: DifférenceFondCaisse | L15: =C15-'17'!C15 -> -38
K16: Total | L16: =(SUM(L10:L15))*-1 -> -274
A18: LIVRAISONS
A19: CODECLIENT | B19: PaiementsChèques | E19: Montant | F19: Banque | G19: Numero | H19: Remarques | L19: SAP
A38: CODECLIENT | B38: PaiementsEspèces | E38: Montant | F38: Remarques | L38: SAP
A48: CODECLIENT | B48: PaiementsCBSite | E48: Montant | F48: Remarques | L48: SAP
A53: CODECLIENT | B53: PaiementsCBTéléphone | E53: Montant | F53: Remarques | L53: SAP
C54: 802.36 | D54: cari versailles
C55: 675.28 | D55: cqfd
C56: 689.72 | D56: cqfd
C57: 340.26 | D57: new
A58: CODECLIENT | B58: Virements | E58: Montant | F58: Remarques | L58: SAP
A65: CODECLIENT | B65: Livraisonsnonpayées | E65: Montant | F65: Remarques | L65: SAP
B80: TOTALESPECES | E80: =SUM(E39:E47) -> 0
B81: TOTALCHEQUES | E81: =SUM(E20:E37) -> 0
B82: TOTALCBInternet&Phone | E82: =SUM(E49:E57) -> 0

Sheet 19
I1: DATE | J1: 46131
E3: RemiseBancaire(SAP) | I3: EXCEL
E4: Espèces | I4: ESPECES | K4: =E80+C14 -> 0
E5: Chèques | I5: CHEQUES | K5: =E15+E81 -> 0
E6: Monnaienondéposée | I6: CARTECREDIT | K6: =G15+E82 -> 0
I7: VIREMENT | K7: =SUM(E59:E64) -> 0
B8: CaisseEspèces | D8: Caissechèques | F8: CaisseCB
B9: Billetsde50 | D9: Client | E9: Montant | F9: Client | G9: Montant | I9: Dépenses:Essence,Divers | L9: Montant
B10: Billetsde20 | F10: Till
B11: Billetsde10 | F11: sancont
B12: Billetsde5
B13: Monnaie
B14: Total | C14: =SUM(C9:C13) -> 0
B15: Fonddecaisse | D15: Total | E15: =SUM(E10:E14) -> 0 | F15: Total | G15: =SUM(G10:G14) -> 0 | I15: DifférenceFondCaisse | L15: =C15-'18'!C15 -> -253
K16: Total | L16: =(SUM(L10:L15))*-1 -> 253
A18: LIVRAISONS
A19: CODECLIENT | B19: PaiementsChèques | E19: Montant | F19: Banque | G19: Numero | H19: Remarques | L19: SAP
A38: CODECLIENT | B38: PaiementsEspèces | E38: Montant | F38: Remarques | L38: SAP
A48: CODECLIENT | B48: PaiementsCBSite | E48: Montant | F48: Remarques | L48: SAP
A53: CODECLIENT | B53: PaiementsCBTéléphone | E53: Montant | F53: Remarques | L53: SAP
C54: 802.36 | D54: cari versailles
C55: 675.28 | D55: cqfd
C56: 689.72 | D56: cqfd
C57: 340.26 | D57: new
A58: CODECLIENT | B58: Virements | E58: Montant | F58: Remarques | L58: SAP
A65: CODECLIENT | B65: Livraisonsnonpayées | E65: Montant | F65: Remarques | L65: SAP
B80: TOTALESPECES | E80: =SUM(E39:E47) -> 0
B81: TOTALCHEQUES | E81: =SUM(E20:E37) -> 0
B82: TOTALCBInternet&Phone | E82: =SUM(E49:E57) -> 0

Sheet 20
G1: NO 01805004 2975 | I1: DATE | J1: 46132
G2: NO 00279905 4125
E3: RemiseBancaire(SAP) | G3: NO 00279910 1880 | I3: EXCEL
E4: Espèces | F4: 10250 | G4: NO 00279893 1270 | I4: ESPECES | K4: =E207+C15 -> 10255.75
E5: Chèques | F5: 4133.3 | G5: NO 8 4133,30 | I5: CHEQUES | K5: =E16+E208 -> 4133.3
E6: Monnaienondéposée | F6: 5.75 | I6: CARTECREDIT | K6: =G16+E209 -> 26068.2
I7: VIREMENT | K7: =SUM(E62:E164) -> 269425.29
B8: CaisseEspèces | D8: Caissechèques | F8: CaisseCB
B9: Billetsde50 | C9: 1500 | D9: Client | E9: Montant | F9: Client | G9: Montant | I9: Dépenses:Essence,Divers | L9: Montant
B10: Billetsde20 | C10: 2500 | D10: AU SUN DINE | E10: 849.92 | F10: Till | G10: 19916.27 | I10: SKANDER | L10: 65
B11: Billetsde10 | C11: 3150 | D11: ALISHAN REST | E11: 708.16 | F11: sancont | I11: SAMIR GASOIL | L11: 140
I12: HOCINE LAVAGE | L12: 20
B13: Billetsde5 | C13: 125 | I13: AHMED GASOIL | L13: 100
B14: Monnaie | I14: ABU BAKAR GASOIL | L14: 80
B15: Total | C15: =SUM(C9:C14) -> 7275 | I15: YOUSRA SALARY | L15: 850
B16: Fonddecaisse | C16: 291 | D16: Total | E16: =SUM(E10:E15) -> 1558.08 | F16: Total | G16: =SUM(G10:G15) -> 19916.27 | I16: DifférenceFondCaisse | L16: =C16-'19'!C15 -> 291
K17: Total | L17: =(SUM(L10:L16))*-1 -> -1546
A19: LIVRAISONS
A20: CODECLIENT | B20: PaiementsChèques | E20: Montant | F20: Banque | G20: Numero | H20: Remarques | L20: SAP
A21: c1640 | B21: ANCREPERIE | E21: 169.17 | F21: bnp | G21: 6704523 | H21: anciennecommande | L21: ok
A22: C6881 | B22: Lapyramide | E22: 373.43 | F22: lcl | G22: 2232929 | L22: ok
A23: C3476 | B23: VICTORIA 168 | E23: 512.81 | F23: SG | G23: 303 | L23: OK
A24: C4561 | B24: Delice du colisee | E24: 454.75 | F24: SG | G24: 1001959 | L24: OK
A25: C1222 | B25: LE RELAIS D'OR | E25: 548.07 | F25: CIC | G25: 2599553 | L25: OK
A26: C6940 | B26: MCV LA VILLETTE | E26: 516.99 | F26: SG | G26: 78 | L26: OK
A39: CODECLIENT | B39: PaiementsEspèces | E39: Montant | F39: Remarques | L39: SAP
A40: c4474 | B40: CASAPRONTO | E40: 400 | F40: reste264,65apayerparvirement | L40: ok
A41: c3017 | B41: PFCARDINET(MATHIEUBoulangerie) | E41: 399.37 | L41: ok
A42: c3404 | B42: O'CROUSTY | E42: 2181.38 | L42: ok
A48: CODECLIENT | B48: PaiementsCBSite | E48: Montant | F48: Remarques | L48: SAP
A49: C6108 | B49: LEROCHER | E49: 316.89 | L49: OK
A50: C1403 | C50: SARLGOKAL | E50: 530.5 | L50: OK
A51: C7550 | C51: AQUAGO | E51: 1627.28 | L51: OK
A52: C4927 | C52: PizzeriaSarda | E52: 2637.79 | L52: OK
A53: C653 | B53: DEDAMASABEYROUTH | E53: 313.76 | L53: OK
A54: C7396 | B54: LESSAVEURSDEGRETZ | E54: 725.71 | L54: OK
A56: CODECLIENT | B56: PaiementsCBTéléphone | E56: Montant | F56: Remarques | L56: SAP
C57: 802.36 | D57: cari versailles
C58: 675.28 | D58: cqfd
C59: 689.72 | D59: cqfd
...

Sheet 21
I1: DATE | J1: 46133
E3: RemiseBancaire(SAP) | G3: NO 01552712 3775 | I3: EXCEL
E4: Espèces | F4: 5855 | G4: NO 01552707 2080 | I4: ESPECES | K4: =E106+C17 -> 5855
E5: Chèques | F5: 5091.62 | G5: NO 8 4699,41 | I5: CHEQUES | K5: =E18+E107 -> 4699.41
E6: Monnaienondéposée | I6: CARTECREDIT | K6: =G18+E108 -> 33181.56
I7: VIREMENT | K7: =SUM(E72:E77) -> 0
B8: CaisseEspèces | D8: Caissechèques | F8: CaisseCB
B9: Billetsde50 | C9: 1200 | D9: Client | E9: Montant | F9: Client | G9: Montant | I9: Dépenses:Essence,Divers | L9: Montant
B10: Billetsde20 | C10: 2300 | D10: ALISHAN REST | E10: 212.89 | F10: Till | G10: 23821.13 | I10: AMOR GASOIL | L10: 150
B11: Billetsde10 | C11: 2030 | D11: MAX CHICKEN | E11: 461.19 | F11: sancont | I11: AMOR SAMDI | L11: 65
I12: HOUCINE GASOIL | L12: 80
I13: SAMIR GASOIL | L13: 250
B14: Billetsde5 | C14: 275 | I14: SAMIR LAVAGE | L14: 50
I15: SKANDAR GASOIL | L15: 85
B16: Monnaie | I16: FIRDAWAS SALARIE | L16: 70
B17: Total | C17: =SUM(C9:C16) -> 5805 | I17: AMOR LAVAGE | L17: 28
B18: Fonddecaisse | C18: 416 | D18: Total | E18: =SUM(E10:E17) -> 674.08 | F18: Total | G18: =SUM(G10:G17) -> 23821.13 | I18: DifférenceFondCaisse | L18: =C18-'20'!C16 -> 125
K19: Total | L19: =(SUM(L10:L18))*-1 -> -903
A21: LIVRAISONS
A22: CODECLIENT | B22: PaiementsChèques | E22: Montant | F22: Banque | G22: Numero | H22: Remarques | L22: SAP
A23: c4204 | B23: Kashmir express | E23: 341.09 | F23: lcl | G23: 2722684 | L23: ok
A24: c6643 | B24: BK FAMILY | E24: 2150.33 | F24: sg | G24: 155 | L24: ok
A25: c5161 | B25: K-CHI | E25: 260.41 | F25: bnp | G25: 9427206 | L25: ok
A26: c4168 | B26: restaurant k- chimaek | E26: 263.57 | F26: bnp | G26: 9427109 | L26: ok
A27: C4647 | B27: TAMKINE 1 | E27: 322.72 | F27: CM | G27: 6375632 | L27: OK
A28: C3237 | B28: LE MAGHREB | E28: 687.21 | F28: LCL | G28: 6786167 | L28: OK
A40: CODECLIENT | B40: PaiementsEspèces | E40: Montant | F40: Remarques | L40: SAP
B41: SAMIR | E41: 50 | F41: RETOUR GASIL
A50: CODECLIENT | B50: PaiementsCBSite | E50: Montant | F50: Remarques | L50: SAP
B51: 12/04/2026 Paiement DCC: Krunchy Sarcelles Terminé | E51: 418.93 | F51: 2.61 | G51: 416.32 | H51: paypal + cash | L51: ok
B52: 13/04/2026 Paiement Express Checkout: SARL EL DORADO Terminé | E52: 1398.24 | F52: 28.21 | G52: 1370.03 | H52: paypal + cash | L52: ok
B53: 13/04/2026 Paiement DCC: Séverine Richard Terminé | E53: 548.2 | F53: 3.39 | G53: 544.81 | H53: paypal + cash | L53: ok
B54: 13/04/2026 Paiement DCC: Sodary KHAMPRASEUTH Terminé | E54: 419.79 | F54: 2.62 | G54: 417.17 | H54: paypal + cash | L54: ok
B55: 13/04/2026 Paiement DCC: Laura Sonzini Terminé | E55: 1911.68 | F55: 11.57 | G55: 1900.11 | H55: paypal + cash | L55: ok
B56: 14/04/2026 Paiement DCC: Pascal Papillon Terminé | E56: 470.59 | F56: 2.92 | G56: 467.67 | H56: paypal + cash | L56: ok
B57: 14/04/2026 Paiement DCC: Golam Azam Terminé | E57: 328.54 | F57: 2.07 | G57: 326.47 | H57: paypal + cash | L57: ok
B58: 14/04/2026 Paiement Express Checkout: OUNISSA YAZID Terminé | E58: 360.35 | F58: 7.46 | G58: 352.89 | H58: paypal + cash | L58: ok
B59: Paiement Express Checkout: SANDRINE 14/04/2026 QUEVILLON Terminé Identifiant: 8HY534866X7790114 | E59: 484.42 | F59: 9.94 | G59: 474.48 | H59: paypal + cash | L59: ok
B60: 17/04/2026 Paiement Express Checkout: thinhung nguyen Terminé | E60: 321.13 | F60: 6.67 | G60: 314.46 | H60: paypal + cash | L60: ok
B61: 17/04/2026 Paiement DCC: mahendran ruhunaveni Terminé | E61: 381.79 | F61: 2.39 | G61: 379.4 | H61: paypal + cash | L61: ok
...

Sheet 22
G1: no 01552747 1950 | I1: DATE | J1: 46134
G2: no 01552727 4560
E3: RemiseBancaire(SAP) | G3: no 01552732 5955 | I3: EXCEL
E4: Espèces | F4: 14120 | G4: no 01552752 1655 | I4: ESPECES | K4: =E85+C14 -> 14126.11
E5: Chèques | F5: 4049.31 | G5: no 10 4049,31 | I5: CHEQUES | K5: =E15+E86 -> 4049.31
E6: Monnaienondéposée | F6: 6.11 | I6: CARTECREDIT | K6: =G15+E87 -> 12502.12
I7: VIREMENT | K7: =SUM(E59:E64) -> 0
B8: CaisseEspèces | D8: Caissechèques | F8: CaisseCB
B9: Billetsde50 | C9: 2000 | D9: Client | E9: Montant | F9: Client | G9: Montant | I9: Dépenses:Essence,Divers | L9: Montant
B10: Billetsde20 | C10: 2060 | D10: alishan rest | E10: 422.91 | F10: Till | G10: 11887.01 | I10: rendu remboursement jk monnaie | L10: 2.83
B11: Billetsde10 | C11: 3400 | F11: sancont | I11: ahmed gasoil | L11: 80
B12: Billetsde5 | C12: 205 | I12: samir lavage | L12: 50
B13: Monnaie
B14: Total | C14: =SUM(C9:C13) -> 7665
B15: Fonddecaisse | C15: 417 | D15: Total | E15: =SUM(E10:E14) -> 422.91 | F15: Total | G15: =SUM(G10:G14) -> 11887.01 | I15: DifférenceFondCaisse | L15: =C15-'21'!C18 -> 1
K16: Total | L16: =(SUM(L10:L15))*-1 -> -133.83
A18: LIVRAISONS
A19: CODECLIENT | B19: PaiementsChèques | E19: Montant | F19: Banque | G19: Numero | H19: Remarques | L19: SAP
A20: c4548 | B20: COTE PIGALLE | E20: 305.84 | F20: bp | G20: 496 | L20: ok
A21: c1855 | B21: FRANPRIX SAVU | E21: 448.6 | F21: lcl | G21: 4142823 | L21: ok
A22: c5144 | B22: MCV FAIDHERBE | E22: 467.01 | F22: bred | G22: 7051124 | L22: ok
A23: c2938 | B23: MCV Dumas | E23: 353.11 | F23: bred | G23: 8738422 | L23: ok
A24: c3647 | B24: AU LEVAIN | E24: 327.84 | F24: la poste | G24: 5673007 | L24: ok
A25: c2545 | B25: BRN TASTY | E25: 511.95 | F25: bp | G25: 1170 | L25: ok
A26: c1900 | B26: HOT PIZZA 77 | E26: 352.12 | F26: cic | G26: 6361490 | L26: ok
A27: c6758 | B27: selimex | E27: 535.52 | F27: sg | G27: 781 | L27: ok
A28: c6599 | B28: Shuaib cassim | E28: 324.41 | F28: lcl | G28: 324.41 | L28: ok
A38: CODECLIENT | B38: PaiementsEspèces | E38: Montant | F38: Remarques | L38: SAP
A39: c6973 | B39: jk distribution | E39: 4510 | F39: surplace | L39: ok
A40: c2414 | B40: LA ROTISSERIE | E40: 413.8 | L40: ok
A41: c5076 | B41: Burger Dpc | E41: 361.89 | L41: ok
A42: c9999 | B42: vente comptoir sur place | E42: 1125.42 | F42: crousty family | L42: ok
B43: samir retour | E43: 50 | F43: samir retour lavage
A48: CODECLIENT | B48: PaiementsCBSite | E48: Montant | F48: Remarques | L48: SAP
A49: c7396 | B49: LES SAVEURS DE GRETZ | E49: 615.11 | L49: ok
A53: CODECLIENT | B53: PaiementsCBTéléphone | E53: Montant | F53: Remarques | L53: SAP
C54: 802.36 | D54: cari versailles
C55: 675.28 | D55: cqfd
C56: 689.72 | D56: cqfd
C57: 340.26 | D57: new
...

Sheet 23
I1: DATE | J1: 46135
E3: RemiseBancaire(SAP) | G3: no 01808819 3920 | I3: EXCEL
E4: Espèces | F4: 7845 | G4: no 01552839 3925 | I4: ESPECES | K4: =E100+C14 -> 7870.34
E5: Chèques | F5: 4274.16 | G5: no 7 4274,16 | I5: CHEQUES | K5: =E15+E101 -> 4274.16
E6: Monnaienondéposée | F6: 25.34 | I6: CARTECREDIT | K6: =G15+E102 -> 37646.45
I7: VIREMENT | K7: =SUM(E70:E75) -> 0
B8: CaisseEspèces | D8: Caissechèques | F8: CaisseCB
B9: Billetsde50 | C9: 2350 | D9: Client | E9: Montant | F9: Client | G9: Montant | I9: Dépenses:Essence,Divers | L9: Montant
B10: Billetsde20 | C10: 2320 | D10: alishan rest | E10: 260.52 | F10: Till | G10: 17024.65 | I10: houcine gasoil | L10: 80
B11: Billetsde10 | C11: 1490 | F11: sancont | I11: skandar gasoil | L11: 80
B12: Billetsde5 | C12: 80 | I12: ahmed gasoil | L12: 80
B13: Monnaie | I13: samir lavage petit camion | L13: 10
B14: Total | C14: =SUM(C9:C13) -> 6240
B15: Fonddecaisse | C15: 383 | D15: Total | E15: =SUM(E10:E14) -> 260.52 | F15: Total | G15: =SUM(G10:G14) -> 17024.65 | I15: DifférenceFondCaisse | L15: =C15-'22'!C18 -> 383
K16: Total | L16: =(SUM(L10:L15))*-1 -> -633
A18: LIVRAISONS
A19: CODECLIENT | B19: PaiementsChèques | E19: Montant | F19: Banque | G19: Numero | H19: Remarques | L19: SAP
A20: C1541 | B20: Sarl Cdr | E20: 359.93 | F20: BP | G20: 6386 | L20: OK
A21: C7637 | B21: CHIKEN FRENZY | E21: 1958.21 | F21: LCL | G21: 6155360 | L21: OK
A22: C5499 | B22: LATIFA AFIF | E22: 566.04 | F22: SG | G22: 18 | L22: OK
A23: C4494 | B23: MCV Daumesnil | E23: 341.55 | F23: BRED | G23: 8622366 | L23: OK
A24: C4299 | B24: les 5 freres | E24: 521.41 | F24: BP | G24: 730 | L24: ok
A25: c1428 | B25: NOUJOUM | E25: 266.5 | F25: caisse d'epargne | G25: 2035 | L25: ok
A38: CODECLIENT | B38: PaiementsEspèces | E38: Montant | F38: Remarques | L38: SAP
A39: C7824 | B39: Polydoros Skliros | E39: 335.47 | L39: OK
A40: C5276 | B40: Silan | E40: 293.21 | L40: OK
A41: C5702 | B41: Fahad Muhammad | E41: 388.11 | L41: OK
A42: C3110 | B42: Artipain | E42: 335.47 | L42: OK
B43: EXTRA PALETTE | E43: 75 | F43: EXTRA | L43: ok
A44: c4646 | B44: extra chicken land | E44: 203.08
A48: CODECLIENT | B48: PaiementsCBSite | E48: Montant | F48: Remarques | L48: SAP
A53: CODECLIENT | B53: PaiementsCBTéléphone | E53: Montant | F53: Remarques | L53: SAP
A54: C6108 | B54: LE ROCHER | C54: 802.36 | D54: cari versailles | E54: 356.95 | L54: OK
A55: C5977 | C55: brandecision | E55: 4788.9 | L55: OK
A56: C6723 | C56: LA PETITE PAUSE | E56: 438.66 | L56: OK
A57: C5170 | C57: FARMER PARIS | E57: 2140.21 | L57: OK
A58: C7191 | C58: O'Tacos-MCL DISTRIBUTION LAUDIER Charles | E58: 538.01 | L58: OK
A59: C7191 | C59: O'Tacos-MCL DISTRIBUTION LAUDIER Charles | E59: 695.91 | L59: OK
A60: C7191 | C60: LI DISTRIBUTION | E60: 239.81 | L60: OK
A61: C6106 | C61: Keanu Gilson | E61: 4028.53 | L61: OK
...

Sheet 24
I1: DATE | J1: 46136
E3: RemiseBancaire(SAP) | G3: no 01552767 4105 | I3: EXCEL
E4: Espèces | F4: 7465 | G4: no 01552772 3360 | I4: ESPECES | K4: =E97+C14 -> 7493.09
E5: Chèques | F5: 4576.14 | G5: no 9 4576,14 | I5: CHEQUES | K5: =E15+E98 -> 4576.14
E6: Monnaienondéposée | F6: 28.09 | I6: CARTECREDIT | K6: =G15+E99 -> 20645.41
I7: VIREMENT | K7: =SUM(E59:E64) -> 0
B8: CaisseEspèces | D8: Caissechèques | F8: CaisseCB
B9: Billetsde50 | C9: 2050 | D9: Client | E9: Montant | F9: Client | G9: Montant | I9: Dépenses:Essence,Divers | L9: Montant
B10: Billetsde20 | C10: 900 | D10: alishan rest | E10: 589.67 | F10: Till | G10: 18456.89 | I10: samir gasoilet et ad blu | L10: 233
B11: Billetsde10 | C11: 1490 | D11: l'emeraude | E11: 669.02 | F11: sancont
B12: Billetsde5 | C12: 410 | D12: 3a food | E12: 213.39
B13: Monnaie
B14: Total | C14: =SUM(C9:C13) -> 4850
B15: Fonddecaisse | C15: 323 | D15: Total | E15: =SUM(E10:E14) -> 1472.08 | F15: Total | G15: =SUM(G10:G14) -> 18456.89 | I15: DifférenceFondCaisse | L15: =C15-'23'!C15 -> -60
K16: Total | L16: =(SUM(L10:L15))*-1 -> -173
A18: LIVRAISONS
A19: CODECLIENT | B19: PaiementsChèques | E19: Montant | F19: Banque | G19: Numero | H19: Remarques | L19: SAP
A20: c3476 | B20: VICTORIA 168 | E20: 697.27 | F20: sg | G20: 304 | L20: ok
A21: c5428 | B21: restaurant sakata xu | E21: 310.53 | F21: bred | G21: 7379318 | L21: ok
